<?xml version="1.0"?> 
<robot name="virat" xmlns:xacro="http://ros.org/wiki/xacro">

	
	<xacro:macro name="default_inertial" params="mass">
		<inertial>
			<origin rpy="0.0 0 0" xyz="0 0 0"/>
			<mass value="${mass}" />
			<inertia ixx="1.0" ixy="0.0" ixz="0.0" iyy="1.0" iyz="0.0" izz="1.0" />
		</inertial>
	</xacro:macro>
	
	<link name="body">
		<visual>

			<origin  xyz="0 0 0"/>
			
			<geometry>
				<mesh filename="package://viratsim/meshes/body/bot2.dae"/>
        		</geometry>
        					

		</visual>
		
		<collision>
			<origin  xyz="0 0 0"/>
			
			<geometry>
				<mesh filename="package://viratsim/meshes/body/bot2.dae"/>
			</geometry>

		</collision>

		<xacro:default_inertial mass="50"/>

	</link>

	<link name="front_wheel">
		<visual>
			<origin  xyz="0 0 0"/>

			<geometry>
				<mesh filename="package://viratsim/meshes/wheels/castors1.dae"/>
        		</geometry>
        		

		</visual>		        
		
		<collision>
			<origin  xyz="0 0 0"/>

			<geometry>
				<mesh filename="package://viratsim/meshes/wheels/castors1.dae"/>
        		</geometry>
		</collision>
			
		<xacro:default_inertial mass="1"/>
	</link>

	<joint name="front_axle" type="continuous">
		<parent link="body"/>
		<child link="front_wheel"/>
		<origin xyz="0.48 0 0.02"/>
		<axis xyz="0 1 0" rpy="0 0 0"/>
	</joint>

	<link name="rear_wheel_1">
		<visual>

			<origin  xyz="0 0 0"/>

			<geometry>
				<mesh filename="package://viratsim/meshes/wheels/tyre1.dae"/>
        		</geometry>
        		
	
		</visual>
		
		<collision>

			<origin  xyz="0 0 0"/>

			<geometry>
				<mesh filename="package://viratsim/meshes/wheels/tyre1.dae"/>
        		</geometry>
        		
		</collision>
					
		<xacro:default_inertial mass="5"/>
	</link>

	<joint name="rear_axle_1" type="continuous">
		<parent link="body"/>
		<child link="rear_wheel_1"/>
		<origin xyz="0 -0.323 0"/>
		<axis xyz="0 1 0" rpy="0 0 0"/>
	</joint>

	<link name="rear_wheel_2">
		<visual>

			<origin  xyz="0 0 0"/>

			<geometry>
				<mesh filename="package://viratsim/meshes/wheels/tyre1.dae"/>
        		</geometry>
        		
	
		</visual>
		
		<collision>

			<origin  xyz="0 0 0"/>

			<geometry>
				<mesh filename="package://viratsim/meshes/wheels/tyre1.dae"/>
        		</geometry>
        		
		</collision>
					
		<xacro:default_inertial mass="5"/>
	</link>

	<joint name="rear_axle_2" type="continuous">
		<parent link="body"/>
		<child link="rear_wheel_2"/>
		<origin xyz="0 0.323 0"/>
		<axis xyz="0 1 0" rpy="0 0 0"/>
	</joint>

	<gazebo reference="camera">
    <sensor type="camera" name="camera">
      <update_rate>30.0</update_rate>
      <camera name="head">
        <horizontal_fov>1.3962634</horizontal_fov>
        <image>
          <width>800</width>
          <height>800</height>
          <format>R8G8B8</format>
        </image>
        <clip>
          <near>0.02</near>
          <far>300</far>
        </clip>
        <noise>
          <type>gaussian</type>
          <mean>0.0</mean>
          <stddev>0.007</stddev>
        </noise>
      </camera>
      <plugin name="camera_controller" filename="libgazebo_ros_camera.so">
        <alwaysOn>true</alwaysOn>
        <updateRate>0.0</updateRate>
        <cameraName>/mybot/camera</cameraName>
        <imageTopicName>image_raw</imageTopicName>
        <cameraInfoTopicName>camera_info</cameraInfoTopicName>
        <frameName>camera</frameName>
        <hackBaseline>0.07</hackBaseline>
        <distortionK1>0.0</distortionK1>
        <distortionK2>0.0</distortionK2>
        <distortionK3>0.0</distortionK3>
        <distortionT1>0.0</distortionT1>
        <distortionT2>0.0</distortionT2>
      </plugin>
    </sensor>
  </gazebo>

  <link name="camera">
    <visual>
      <geometry>
        <box size="0.05 0.05 0.05"/>
      </geometry>
    </visual>
    <collision>
      <geometry>
        <box size="0.05 0.05 0.05"/>
      </geometry>
    </collision>
    <xacro:default_inertial mass="0.02"/>
  </link>

  <joint name="camera_joint" type="fixed">
    <origin xyz="0.73 0 1.18" rpy="0 0.45 0"/>
    <parent link="body"/>
    <child link="camera"/>
  </joint>

</robot>