<?xml version="1.0"?>
<robot name="virat" xmlns:xacro="http://ros.org/wiki/xacro">>
	<link name="body">
		<visual>
			<geometry>
				<mesh filename="package://viratsim/meshes/body/bot2.dae"/>
        		</geometry>
        		
			<origin rpy="0.0 0 0" xyz="0 0 0"/>
		</visual>
	</link>
	
	<link name="front_wheel">
		<visual>
			
			<origin rpy="0.0 0 0" xyz="0.5 0 0"/>
			
			<geometry>
				<mesh filename="package://viratsim/meshes/wheels/castors1.dae"/>
        		</geometry>
        		
			
		</visual>
	</link>
	
	<joint name="front_axle" type="continuous">
		<parent link="body"/>
		<child link="front_wheel"/>
		<origin xyz="0.5 0 0.05"/>
	</joint>
	
	<link name="rear_wheel">
		<visual>
			
			<origin rpy="0.0 0 0" xyz="0 0 0"/>
			
			<geometry>
				<mesh filename="package://viratsim/meshes/wheels/tyre1.dae"/>
        		</geometry>
        		
			
		</visual>
	</link>
	
	<joint name="rear_axle" type="continuous">
		<parent link="body"/>
		<child link="rear_wheel"/>
		<origin xyz="0 0 0"/>
	</joint>
</robot>
